Workbook

Sheet Inputs
A1: Atliq ContractLens: cost estimation inputs
A2: Blue = input you can change (yellow = key assumption to confirm). Black = formula. Every other sheet reads from here.
A4: VOLUME
A5: Contracts reviewed per month today | B5: 9 | D5: PRD 2.3: volume went from 5 to 9 a month in one year.
A6: Contracts per month, target capacity | B6: 15 | D6: PRD success metric: 9 to 15 a month without extra reviewers.
A7: Reviews per contract (first draft + revised drafts) | B7: 1.5 | D7: Assumption: half of drafts come back once with the client's changes.
A8: New signed contracts per month (added to the register) | B8: 6 | D8: Assumption: about two thirds of reviewed drafts are signed.
A9: Signed archive to load once (17 files + 13 the tracker lists) | B9: 30 | D9: Dataset: 17 signed files; tracker lists 13 more signed with no file.
A10: Short signed documents per month (waivers, letters, amendments) | B10: 2 | D10: Assumption.
A11: 'Ask the contracts' questions per month | B11: 80 | D11: Assumption: Karandeep plus four sellers, about one question per working day each.
A12: TOKENS
A13: Tokens in a real incoming contract | B13: 15000 | D13: PRD 5: real contracts are 10,000 to 30,000 tokens. The synthetic drafts average about 2,900 (174,237 characters / 15 files / 4).
A14: Tokens in a real signed contract | B14: 15000 | D14: Assumption, same range as drafts. Synthetic signed files average about 2,250.
A15: Tokens in a short signed document | B15: 3000 | D15: Assumption.
A16: Clause-scan part size (tokens) | B16: 3500 | D16: config.SCAN_CHARS = 14,000 characters, about 3,500 tokens per part.
A17: Clause-scan instructions + playbook per part (tokens) | B17: 1500 | D17: review_graph.py SCAN_SYSTEM plus the playbook rules for AtliQ's role.
A18: Clause-scan output per part (tokens) | B18: 800 | D18: Average; capped at 2,000 (GROQ_MAX_TOKENS).
A19: Extraction input (first 15,000 characters + prompt) | B19: 4050 | D19: review_graph.extract reads text[:15000] (about 3,750 tokens) + 300 prompt.
A20: Extraction output (tokens) | B20: 300 | D20: JSON fields; capped at 500.
A21: Share of reviews with a register hit (conflict check runs) | B21: 0.4 | D21: Dataset: 6 of 15 drafts hit the register.
A22: Conflict-check input per review (tokens) | B22: 3000 | D22: Register entries + the draft passages most related to them.
A23: Conflict-check output per review (tokens) | B23: 600
A24: Register extraction prompt per signed document (tokens) | B24: 400 | D24: register.PROPOSE_SYSTEM
A25: Register extraction output per signed document (tokens) | B25: 1000 | D25: capped at 1,500
A26: 'Ask' input per question (6 retrieved clauses + prompt + history) | B26: 4000 | D26: TOP_K = 6 clause chunks
A27: 'Ask' output per question (tokens) | B27: 400
A28: Retries and re-runs overhead | B28: 0.2 | D28: Assumption: 20% extra calls for retries, re-runs and testing.
A29: INFRASTRUCTURE ($ per month)
A30: Vercel hosting, prototype (Hobby) | B30: 0 | D30: Vercel Hobby is free but for non-commercial use.
A31: Vercel hosting, production (Pro, 1 seat) | B31: 20 | D31: Vercel Pro list price per seat per month.
A32: Storage + logs + backups | B32: 10 | D32: Assumption: reviews and audit log in a small managed database / blob store.
A33: BUSINESS ($)
A34: Rupees per US dollar | B34: 84 | D34: Assumption, Oct 2026.
A35: Value of one hour of Karandeep's time ($) | B35: 150 | D35: Assumption: CEO opportunity cost (selling, running AtliQ). Change to your own figure.
A36: Karandeep's hours per contract today | B36: 3.5 | D36: PRD 2: 3 to 4 hours per contract.
A37: Karandeep's hours per contract with ContractLens | B37: 0.5 | D37: Assumption: read the brief, decide each flag, send the outcome email.
A38: Outside counsel fee per complex review (₹) | B38: 120000 | D38: PRD 2.3: about ₹1,20,000 and 5 to 7 working days.
A39: Counsel reviews per month today | B39: 2 | D39: Assumption: 'the big ones'.
A40: Counsel reviews per month with ContractLens | B40: 1 | D40: Assumption: only blockers on a signed restriction, patient data or liability go to counsel, with a short brief.
A41: Brightwater-type incidents per year today | B41: 1 | D41: Brightwater 2025-26: one contract signed with uncapped LD and English law.
...

Sheet Cost Savings
D3: Calculating Karandeep's review hours
D4: Component | E4: Quantity
D5: Contracts reviewed per month | E5: =Inputs!$B$5 -> 9
D6: Hours per contract without AI | E6: =Inputs!$B$36 -> 3.5
D7: Hours per contract with ContractLens | E7: =Inputs!$B$37 -> 0.5
D8: Hours per month without AI | E8: =E5*E6 -> 31.5
D9: Hours per month with ContractLens | E9: =E5*E7 -> 4.5
D10: Hours given back per month | E10: =E8-E9 -> 27
D13: Total monthly cost without AI
D14: Component | E14: Cost
D15: Karandeep's review time (hours x $150) | E15: =E8*Inputs!$B$35 -> 4725
D16: Outside counsel (2 reviews x ₹1,20,000) | E16: =Inputs!$B$39*Inputs!$B$38/Inputs!$B$34 -> 2857.1429
D17: Expected incident cost (Brightwater-type, per month) | E17: =Inputs!$B$41*Cost_of_Status_Quo!B10/12 -> 2933.3333
D19: Total monthly cost without AI | E19: =SUM(E15:E17) -> 10515.476
D22: Cost with ContractLens (per month)
D23: Component | E23: Cost
D24: Inference cost (model calls, recommended mix) | E24: =Way1_Per_Review!J25 -> 3.030831
D25: Embeddings cost | E25: =Embeddings!D29 -> 0.087161607
D26: Hosting + storage | E26: =Inputs!$B$31+Inputs!$B$32 -> 30
D27: Karandeep's review time (hours x $150) | E27: =E9*Inputs!$B$35 -> 675
D28: Outside counsel (1 review, with a ready brief) | E28: =Inputs!$B$40*Inputs!$B$38/Inputs!$B$34 -> 1428.5714
D29: Expected incident cost (80% caught) | E29: =E17*(1-Inputs!$B$42) -> 586.66667
D31: Total monthly cost with ContractLens | E31: =SUM(E24:E29) -> 2723.3561
D34: Total Savings (per month) | E34: =E19-E31 -> 7792.1201
D35: % Savings | E35: =E34/E19 -> 0.74101448
D36: Total Savings (per year) | E36: =E34*12 -> 93505.441
D38: Hours, rates and counsel volumes are assumptions on the Inputs sheet (yellow cells).

Sheet Inference
B4: Base Calculation (one contract review) | E4: Model Selection + Cost Estimation (per review, all tokens at one model)
B5: Description | C5: Quantity | E5: Model Name | F5: Input cost($) per 1M token | G5: Output cost($) per 1M token | H5: Cost per input Query($) | I5: Cost per output query Query($) | J5: Total Cost per query | K5: Total cost per month
B6: Draft text sent to the clause scan (6 parts x 3,500) | C6: =ROUNDUP(Inputs!$B$13/Inputs!$B$16,0)*Inputs!$B$16 -> 17500 | E6: Groq Llama 3.3 70B | F6: =INDEX(Inputs!$B$50:$B$54,MATCH(E6,Inputs!$A$50:$A$54,0)) -> 0.59 | G6: =INDEX(Inputs!$C$50:$C$54,MATCH(E6,Inputs!$A$50:$A$54,0)) -> 0.79 | H6: =F6*$C$11/1000000 -> 0.021417 | I6: =G6*$C$12/1000000 -> 0.00430392 | J6: =H6+I6 -> 0.02572092 | K6: =J6*$C$16 -> 0.34723242
B7: System prompt + playbook rules (per scan part) | C7: =ROUNDUP(Inputs!$B$13/Inputs!$B$16,0)*Inputs!$B$17 -> 7500 | E7: Groq Llama 3.1 8B | F7: =INDEX(Inputs!$B$50:$B$54,MATCH(E7,Inputs!$A$50:$A$54,0)) -> 0.05 | G7: =INDEX(Inputs!$C$50:$C$54,MATCH(E7,Inputs!$A$50:$A$54,0)) -> 0.08 | H7: =F7*$C$11/1000000 -> 0.001815 | I7: =G7*$C$12/1000000 -> 0.00043584 | J7: =H7+I7 -> 0.00225084 | K7: =J7*$C$16 -> 0.03038634
B8: Extraction: first 15,000 characters + prompt | C8: =Inputs!$B$19 -> 4050 | E8: Claude Haiku 5.5 | F8: =INDEX(Inputs!$B$50:$B$54,MATCH(E8,Inputs!$A$50:$A$54,0)) -> 0.1 | G8: =INDEX(Inputs!$C$50:$C$54,MATCH(E8,Inputs!$A$50:$A$54,0)) -> 0.5 | H8: =F8*$C$11/1000000 -> 0.00363 | I8: =G8*$C$12/1000000 -> 0.002724 | J8: =H8+I8 -> 0.006354 | K8: =J8*$C$16 -> 0.085779
B9: Signed-contract register + passages (conflict check, 40% of reviews) | C9: =Inputs!$B$21*Inputs!$B$22 -> 1200 | E9: Claude Sonnet 5.5 | F9: =INDEX(Inputs!$B$50:$B$54,MATCH(E9,Inputs!$A$50:$A$54,0)) -> 2 | G9: =INDEX(Inputs!$C$50:$C$54,MATCH(E9,Inputs!$A$50:$A$54,0)) -> 10 | H9: =F9*$C$11/1000000 -> 0.0726 | I9: =G9*$C$12/1000000 -> 0.05448 | J9: =H9+I9 -> 0.12708 | K9: =J9*$C$16 -> 1.71558
B10: Retries and re-runs (20%) | C10: =SUM(C6:C9)*Inputs!$B$28 -> 6050 | E10: Claude Opus 5.5 | F10: =INDEX(Inputs!$B$50:$B$54,MATCH(E10,Inputs!$A$50:$A$54,0)) -> 4 | G10: =INDEX(Inputs!$C$50:$C$54,MATCH(E10,Inputs!$A$50:$A$54,0)) -> 20 | H10: =F10*$C$11/1000000 -> 0.1452 | I10: =G10*$C$12/1000000 -> 0.10896 | J10: =H10+I10 -> 0.25416 | K10: =J10*$C$16 -> 3.43116
B11: Total input tokens per review | C11: =SUM(C6:C10) -> 36300 | E11: Recommended mix (Sonnet 5.5 + Haiku 5.5 for extraction) | J11: =Way1_Per_Review!J17 -> 0.114426 | K11: =J11*$C$16 -> 1.544751
B12: Total output tokens per review (incl. retries) | C12: =(ROUNDUP(Inputs!$B$13/Inputs!$B$16,0)*Inputs!$B$18+Inputs!$B$20+Inputs!$B$21*Inputs!$B$23)*(1+Inputs!$B$28) -> 5448
B13: Total tokens per review | C13: =C11+C12 -> 41748 | E13: Monthly ContractLens bill, recommended mix
B14: Contract reviews per working day (9 contracts x 1.5 drafts / 22) | C14: =Inputs!$B$5*Inputs!$B$7/C15 -> 0.61363636 | E14: Contract reviews (row 11) | K14: =K11 -> 1.544751
B15: Working days per month | C15: 22 | E15: Signed contracts + short documents into the register | K15: =Way1_Per_Review!J22+Way1_Per_Review!J23 -> 0.33408
B16: Total monthly volume of reviews | C16: =C14*C15 -> 13.5 | E16: 'Ask the contracts' questions | K16: =Way1_Per_Review!J24 -> 1.152
E17: Embeddings (Embeddings sheet) | K17: =Embeddings!D29 -> 0.087161607
E18: Hosting + storage (Vercel Pro) | K18: =Inputs!$B$31+Inputs!$B$32 -> 30
E19: Total per month | K19: =SUM(K14:K18) -> 33.117993
E20: Total per year | K20: =K19*12 -> 397.41591
E21: Token sizes assume real contracts of ~20,000 tokens (PRD). Prices from the Inputs sheet.

Sheet Embeddings
C3: Token/word | D3: 1.3
C5: Signed contracts (archive, one-time) | F5: Incoming drafts (per month) | I5: Notes + short documents (per month)
C6: Component | D6: Quantity | F6: Component | G6: Quantity | I6: Component | J6: Quantity
C7: Number of signed contracts | D7: =Inputs!$B$9 -> 30 | F7: Number of draft reviews | G7: =Inputs!$B$5*Inputs!$B$7 -> 13.5 | I7: Number of notes + short documents | J7: =4+Inputs!$B$10 -> 6
C8: Number of words per contract | D8: =ROUND(Inputs!$B$14/D3,0) -> 11538 | F8: Number of words per draft | G8: =ROUND(Inputs!$B$13/D3,0) -> 11538 | I8: Number of words per document | J8: 2000
C9: Total number of words | D9: =D7*D8 -> 346140 | F9: Total number of words | G9: =G8*G7 -> 155763 | I9: Total number of words | J9: =J8*J7 -> 12000
C10: Total Tokens | D10: =D9*D3 -> 449982 | F10: Total tokens | G10: =G9*D3 -> 202491.9 | I10: Total tokens | J10: =J9*D3 -> 15600
C13: Document embeddings (archive once + one month of new documents)
C14: Component | D14: Cost/Quantity
C15: Total tokens for RAG | D15: =D10+G10+J10 -> 668073.9
C16: Cost per 1M tokens (embedding model) | D16: 0.13
C17: Total cost for RAG | D17: =D15*D16/1000000 -> 0.086849607
C20: User Query Embeddings
C21: Component | D21: Cost/Quantity
C22: Tokens per question | D22: 30
C23: 'Ask the contracts' questions per month | D23: =Inputs!$B$11 -> 80
C24: Token tokens per month | D24: =D23*D22 -> 2400
C25: Cost per 1M token | D25: =D16 -> 0.13
C26: Total cost for user query embeddings | D26: =D24*D25/1000000 -> 0.000312
C29: Total cost of Embeddings | D29: =D17+D26 -> 0.087161607
C31: Prototype: Vercel uses keyword search (BM25) and the laptop uses a free local model (all-MiniLM-L6-v2), so embeddings cost $0 today. $0.13 per 1M tokens is a paid embedding API for production (assumption).

Sheet Summary
A1: Atliq ContractLens: cost estimation summary
A2: All figures are formulas over the Inputs sheet. Yellow inputs are assumptions to confirm with Karandeep.
A4: Running cost of ContractLens | B4: A Prototype | C4: B Recommended | D4: C Premium
A5: Model cost per review (Way 1, incl. retries) | B5: =Way1_Per_Review!I17 -> 0.02572092 | C5: =Way1_Per_Review!J17 -> 0.114426 | D5: =Way1_Per_Review!K17 -> 0.25416
A6: Cost per contract incl. hosting (today's volume) | B6: =Way1_Per_Review!I31 -> 0.07577178 | C6: =Way1_Per_Review!J31 -> 3.6700923 | D6: =Way1_Per_Review!K31 -> 4.0448133
A7: Per month, today's 9 contracts (Way 1) | B7: =Way1_Per_Review!I27 -> 0.68194602 | C7: =Way1_Per_Review!J27 -> 33.030831 | D7: =Way1_Per_Review!K27 -> 36.40332
A8: Per year, today's volume (Way 1) | B8: =Way1_Per_Review!I28 -> 8.1833522 | C8: =Way1_Per_Review!J28 -> 396.36997 | D8: =Way1_Per_Review!K28 -> 436.83984
A9: Per year at 15 contracts a month (Way 1) | B9: =Way1_Per_Review!I29 -> 13.63892 | C9: =Way1_Per_Review!J29 -> 420.61662 | D9: =Way1_Per_Review!K29 -> 488.0664
A10: One-time: signed archive into the register | B10: =Way1_Per_Review!I30 -> 0.355536 | C10: =Way1_Per_Review!J30 -> 1.4688 | D10: =Way1_Per_Review!K30 -> 2.9376
A11: Per year, today's volume (Way 2 cross-check) | B11: =Way2_Tokens_By_Document!J15 -> 7.7933858 | C11: =Way2_Tokens_By_Document!K15 -> 397.098 | D11: =Way2_Tokens_By_Document!L15 -> 434.196
A13: Business case (scenario B, per year) | B13: Without AI | C13: With ContractLens | D13: Saving
A14: Karandeep's review time | B14: =Cost_of_Status_Quo!B28 -> 56700 | C14: =Cost_of_Status_Quo!C28 -> 8100 | D14: =Cost_of_Status_Quo!E28 -> 48600
A15: Outside counsel | B15: =Cost_of_Status_Quo!B29 -> 34285.714 | C15: =Cost_of_Status_Quo!C29 -> 17142.857 | D15: =Cost_of_Status_Quo!E29 -> 17142.857
A16: Expected incident cost | B16: =Cost_of_Status_Quo!B30 -> 35200 | C16: =Cost_of_Status_Quo!C30 -> 7040 | D16: =Cost_of_Status_Quo!E30 -> 28160
A17: ContractLens model + hosting | B17: =Cost_of_Status_Quo!B31 -> 0 | C17: =Cost_of_Status_Quo!C31 -> 396.36997 | D17: =Cost_of_Status_Quo!E31 -> -396.36997
A18: Total per year | B18: =Cost_of_Status_Quo!B32 -> 126185.71 | C18: =Cost_of_Status_Quo!C32 -> 32679.227 | D18: =Cost_of_Status_Quo!E32 -> 93506.487
A19: Karandeep's hours on contracts per month | B19: =Cost_of_Status_Quo!B33 -> 31.5 | C19: =Cost_of_Status_Quo!C33 -> 4.5
A20: One-time cost to go live | C20: =Cost_of_Status_Quo!C34 -> 5701.4688
A21: Payback (months) | C21: =Cost_of_Status_Quo!C35 -> 0.73168855
A22: Saving per $1 spent on running ContractLens | C22: =Cost_of_Status_Quo!C36 -> 235.90709
A24: What is at stake right now | B24: Value
A25: Deal value waiting on review | B25: =Cost_of_Status_Quo!B22 -> 740000
A26: Deals carrying a blocker-level risk | B26: =Cost_of_Status_Quo!B23 -> 600000
A27: Al Noor contract a missed conflict would breach | B27: =Cost_of_Status_Quo!B24 -> 185000
A28: Cost of one Brightwater-type incident | B28: =Cost_of_Status_Quo!B10 -> 35200
A30: Sheets: Inference, Embeddings and Cost Savings follow the Session 9 master-sheet format. Way1_Per_Review costs each workflow step; Way2_Tokens_By_Document counts input/output tokens by document type; Cost_of_Status_Quo compares with past losses and deals in hand. All inputs are on the Inputs sheet.

Sheet Way1_Per_Review
A1: Way 1: cost by workflow step (how ContractLens actually runs a review)
A2: Each review runs 11 steps. 8 are plain code and cost nothing per call; only 3 send text to a model. Token sizes come from Inputs.
A4: Step | B4: Done by | C4: Model | D4: Calls per review | E4: Input tokens per call | F4: Output tokens per call | G4: Input tokens per review | H4: Output tokens per review | I4: Cost/review A Prototype | J4: Cost/review B Recommended | K4: Cost/review C Premium
A5: 1. Personal-data gate | B5: code | C5: none | D5: 1 | E5: 0 | F5: 0 | G5: =D5*E5 -> 0 | H5: =D5*F5 -> 0 | I5: =IF(C5="main",G5*Inputs!$B$64+H5*Inputs!$C$64,IF(C5="fast",G5*Inputs!$D$64+H5*Inputs!$E$64,0))/1000000 -> 0 | J5: =IF(C5="main",G5*Inputs!$B$65+H5*Inputs!$C$65,IF(C5="fast",G5*Inputs!$D$65+H5*Inputs!$E$65,0))/1000000 -> 0 | K5: =IF(C5="main",G5*Inputs!$B$66+H5*Inputs!$C$66,IF(C5="fast",G5*Inputs!$D$66+H5*Inputs!$E$66,0))/1000000 -> 0
A6: 2. Extract fields (parties, law, places) | B6: AI | C6: fast | D6: 1 | E6: =Inputs!$B$19 -> 4050 | F6: =Inputs!$B$20 -> 300 | G6: =D6*E6 -> 4050 | H6: =D6*F6 -> 300 | I6: =IF(C6="main",G6*Inputs!$B$64+H6*Inputs!$C$64,IF(C6="fast",G6*Inputs!$D$64+H6*Inputs!$E$64,0))/1000000 -> 0.0026265 | J6: =IF(C6="main",G6*Inputs!$B$65+H6*Inputs!$C$65,IF(C6="fast",G6*Inputs!$D$65+H6*Inputs!$E$65,0))/1000000 -> 0.000555 | K6: =IF(C6="main",G6*Inputs!$B$66+H6*Inputs!$C$66,IF(C6="fast",G6*Inputs!$D$66+H6*Inputs!$E$66,0))/1000000 -> 0.0222
A7: 3. Rule checks: entity, law, bundle, NDA, annexes | B7: code | C7: none | D7: 1 | E7: 0 | F7: 0 | G7: =D7*E7 -> 0 | H7: =D7*F7 -> 0 | I7: =IF(C7="main",G7*Inputs!$B$64+H7*Inputs!$C$64,IF(C7="fast",G7*Inputs!$D$64+H7*Inputs!$E$64,0))/1000000 -> 0 | J7: =IF(C7="main",G7*Inputs!$B$65+H7*Inputs!$C$65,IF(C7="fast",G7*Inputs!$D$65+H7*Inputs!$E$65,0))/1000000 -> 0 | K7: =IF(C7="main",G7*Inputs!$B$66+H7*Inputs!$C$66,IF(C7="fast",G7*Inputs!$D$66+H7*Inputs!$E$66,0))/1000000 -> 0
A8: 4. Register check (signed promises) | B8: code | C8: none | D8: 1 | E8: 0 | F8: 0 | G8: =D8*E8 -> 0 | H8: =D8*F8 -> 0 | I8: =IF(C8="main",G8*Inputs!$B$64+H8*Inputs!$C$64,IF(C8="fast",G8*Inputs!$D$64+H8*Inputs!$E$64,0))/1000000 -> 0 | J8: =IF(C8="main",G8*Inputs!$B$65+H8*Inputs!$C$65,IF(C8="fast",G8*Inputs!$D$65+H8*Inputs!$E$65,0))/1000000 -> 0 | K8: =IF(C8="main",G8*Inputs!$B$66+H8*Inputs!$C$66,IF(C8="fast",G8*Inputs!$D$66+H8*Inputs!$E$66,0))/1000000 -> 0
A9: 5. Repeat check (already signed / seen before) | B9: code | C9: none | D9: 1 | E9: 0 | F9: 0 | G9: =D9*E9 -> 0 | H9: =D9*F9 -> 0 | I9: =IF(C9="main",G9*Inputs!$B$64+H9*Inputs!$C$64,IF(C9="fast",G9*Inputs!$D$64+H9*Inputs!$E$64,0))/1000000 -> 0 | J9: =IF(C9="main",G9*Inputs!$B$65+H9*Inputs!$C$65,IF(C9="fast",G9*Inputs!$D$65+H9*Inputs!$E$65,0))/1000000 -> 0 | K9: =IF(C9="main",G9*Inputs!$B$66+H9*Inputs!$C$66,IF(C9="fast",G9*Inputs!$D$66+H9*Inputs!$E$66,0))/1000000 -> 0
A10: 6. Retrieve passages (keyword search) | B10: code | C10: none | D10: 1 | E10: 0 | F10: 0 | G10: =D10*E10 -> 0 | H10: =D10*F10 -> 0 | I10: =IF(C10="main",G10*Inputs!$B$64+H10*Inputs!$C$64,IF(C10="fast",G10*Inputs!$D$64+H10*Inputs!$E$64,0))/1000000 -> 0 | J10: =IF(C10="main",G10*Inputs!$B$65+H10*Inputs!$C$65,IF(C10="fast",G10*Inputs!$D$65+H10*Inputs!$E$65,0))/1000000 -> 0 | K10: =IF(C10="main",G10*Inputs!$B$66+H10*Inputs!$C$66,IF(C10="fast",G10*Inputs!$D$66+H10*Inputs!$E$66,0))/1000000 -> 0
A11: 7. AI clause scan vs playbook | B11: AI | C11: main | D11: =ROUNDUP(Inputs!$B$13/Inputs!$B$16,0) -> 5 | E11: =Inputs!$B$16+Inputs!$B$17 -> 5000 | F11: =Inputs!$B$18 -> 800 | G11: =D11*E11 -> 25000 | H11: =D11*F11 -> 4000 | I11: =IF(C11="main",G11*Inputs!$B$64+H11*Inputs!$C$64,IF(C11="fast",G11*Inputs!$D$64+H11*Inputs!$E$64,0))/1000000 -> 0.01791 | J11: =IF(C11="main",G11*Inputs!$B$65+H11*Inputs!$C$65,IF(C11="fast",G11*Inputs!$D$65+H11*Inputs!$E$65,0))/1000000 -> 0.09 | K11: =IF(C11="main",G11*Inputs!$B$66+H11*Inputs!$C$66,IF(C11="fast",G11*Inputs!$D$66+H11*Inputs!$E$66,0))/1000000 -> 0.18
A12: 8. AI conflict check (explains register hits) | B12: AI | C12: main | D12: =Inputs!$B$21 -> 0.4 | E12: =Inputs!$B$22 -> 3000 | F12: =Inputs!$B$23 -> 600 | G12: =D12*E12 -> 1200 | H12: =D12*F12 -> 240 | I12: =IF(C12="main",G12*Inputs!$B$64+H12*Inputs!$C$64,IF(C12="fast",G12*Inputs!$D$64+H12*Inputs!$E$64,0))/1000000 -> 0.0008976 | J12: =IF(C12="main",G12*Inputs!$B$65+H12*Inputs!$C$65,IF(C12="fast",G12*Inputs!$D$65+H12*Inputs!$E$65,0))/1000000 -> 0.0048 | K12: =IF(C12="main",G12*Inputs!$B$66+H12*Inputs!$C$66,IF(C12="fast",G12*Inputs!$D$66+H12*Inputs!$E$66,0))/1000000 -> 0.0096
A13: 9. Citation check (quote must be verbatim) | B13: code | C13: none | D13: 1 | E13: 0 | F13: 0 | G13: =D13*E13 -> 0 | H13: =D13*F13 -> 0 | I13: =IF(C13="main",G13*Inputs!$B$64+H13*Inputs!$C$64,IF(C13="fast",G13*Inputs!$D$64+H13*Inputs!$E$64,0))/1000000 -> 0 | J13: =IF(C13="main",G13*Inputs!$B$65+H13*Inputs!$C$65,IF(C13="fast",G13*Inputs!$D$65+H13*Inputs!$E$65,0))/1000000 -> 0 | K13: =IF(C13="main",G13*Inputs!$B$66+H13*Inputs!$C$66,IF(C13="fast",G13*Inputs!$D$66+H13*Inputs!$E$66,0))/1000000 -> 0
A14: 10. Brief + severity from playbook | B14: code | C14: none | D14: 1 | E14: 0 | F14: 0 | G14: =D14*E14 -> 0 | H14: =D14*F14 -> 0 | I14: =IF(C14="main",G14*Inputs!$B$64+H14*Inputs!$C$64,IF(C14="fast",G14*Inputs!$D$64+H14*Inputs!$E$64,0))/1000000 -> 0 | J14: =IF(C14="main",G14*Inputs!$B$65+H14*Inputs!$C$65,IF(C14="fast",G14*Inputs!$D$65+H14*Inputs!$E$65,0))/1000000 -> 0 | K14: =IF(C14="main",G14*Inputs!$B$66+H14*Inputs!$C$66,IF(C14="fast",G14*Inputs!$D$66+H14*Inputs!$E$66,0))/1000000 -> 0
A15: 11. Outcome email from decisions | B15: code | C15: none | D15: 1 | E15: 0 | F15: 0 | G15: =D15*E15 -> 0 | H15: =D15*F15 -> 0 | I15: =IF(C15="main",G15*Inputs!$B$64+H15*Inputs!$C$64,IF(C15="fast",G15*Inputs!$D$64+H15*Inputs!$E$64,0))/1000000 -> 0 | J15: =IF(C15="main",G15*Inputs!$B$65+H15*Inputs!$C$65,IF(C15="fast",G15*Inputs!$D$65+H15*Inputs!$E$65,0))/1000000 -> 0 | K15: =IF(C15="main",G15*Inputs!$B$66+H15*Inputs!$C$66,IF(C15="fast",G15*Inputs!$D$66+H15*Inputs!$E$66,0))/1000000 -> 0
A16: Per review (before retries) | G16: =SUM(G5:G15) -> 30250 | H16: =SUM(H5:H15) -> 4540 | I16: =SUM(I5:I15) -> 0.0214341 | J16: =SUM(J5:J15) -> 0.095355 | K16: =SUM(K5:K15) -> 0.2118
A17: Per review incl. retries | I17: =I16*(1+Inputs!$B$28) -> 0.02572092 | J17: =J16*(1+Inputs!$B$28) -> 0.114426 | K17: =K16*(1+Inputs!$B$28) -> 0.25416
A19: Monthly and yearly cost
A20: Item | D20: Per month (today 9) | I20: A Prototype | J20: B Recommended | K20: C Premium
A21: Contract reviews (incl. revised drafts) | D21: =Inputs!$B$5*Inputs!$B$7 -> 13.5 | I21: =$D21*I$17 -> 0.34723242 | J21: =$D21*J$17 -> 1.544751 | K21: =$D21*K$17 -> 3.43116
A22: New signed contracts into the register | D22: =Inputs!$B$8 -> 6 | I22: =$D22*((Inputs!$B$14+Inputs!$B$24)*Inputs!$B$64+Inputs!$B$25*Inputs!$C$64)/1000000*(1+Inputs!$B$28) -> 0.0711072 | J22: =$D22*((Inputs!$B$14+Inputs!$B$24)*Inputs!$B$65+Inputs!$B$25*Inputs!$C$65)/1000000*(1+Inputs!$B$28) -> 0.29376 | K22: =$D22*((Inputs!$B$14+Inputs!$B$24)*Inputs!$B$66+Inputs!$B$25*Inputs!$C$66)/1000000*(1+Inputs!$B$28) -> 0.58752
A23: Short signed documents into the register | D23: =Inputs!$B$10 -> 2 | I23: =$D23*((Inputs!$B$15+Inputs!$B$24)*Inputs!$B$64+Inputs!$B$25*Inputs!$C$64)/1000000*(1+Inputs!$B$28) -> 0.0067104 | J23: =$D23*((Inputs!$B$15+Inputs!$B$24)*Inputs!$B$65+Inputs!$B$25*Inputs!$C$65)/1000000*(1+Inputs!$B$28) -> 0.04032 | K23: =$D23*((Inputs!$B$15+Inputs!$B$24)*Inputs!$B$66+Inputs!$B$25*Inputs!$C$66)/1000000*(1+Inputs!$B$28) -> 0.08064
A24: 'Ask the contracts' questions | D24: =Inputs!$B$11 -> 80 | I24: =$D24*(Inputs!$B$26*Inputs!$B$64+Inputs!$B$27*Inputs!$C$64)/1000000*(1+Inputs!$B$28) -> 0.256896 | J24: =$D24*(Inputs!$B$26*Inputs!$B$65+Inputs!$B$27*Inputs!$C$65)/1000000*(1+Inputs!$B$28) -> 1.152 | K24: =$D24*(Inputs!$B$26*Inputs!$B$66+Inputs!$B$27*Inputs!$C$66)/1000000*(1+Inputs!$B$28) -> 2.304
A25: Model cost per month | I25: =SUM(I21:I24) -> 0.68194602 | J25: =SUM(J21:J24) -> 3.030831 | K25: =SUM(K21:K24) -> 6.40332
A26: Hosting + storage per month | I26: =Inputs!$B$30 -> 0 | J26: =Inputs!$B$31+Inputs!$B$32 -> 30 | K26: =Inputs!$B$31+Inputs!$B$32 -> 30
A27: Total per month (today's volume) | I27: =I25+I26 -> 0.68194602 | J27: =J25+J26 -> 33.030831 | K27: =K25+K26 -> 36.40332
A28: Total per year (today's volume) | I28: =I27*12 -> 8.1833522 | J28: =J27*12 -> 396.36997 | K28: =K27*12 -> 436.83984
A29: Total per year at target volume (15 a month) | I29: =(I25*Inputs!$B$6/Inputs!$B$5+I26)*12 -> 13.63892 | J29: =(J25*Inputs!$B$6/Inputs!$B$5+J26)*12 -> 420.61662 | K29: =(K25*Inputs!$B$6/Inputs!$B$5+K26)*12 -> 488.0664
A30: One-time: load the signed archive into the register | I30: =Inputs!$B$9*((Inputs!$B$14+Inputs!$B$24)*Inputs!$B$64+Inputs!$B$25*Inputs!$C$64)/1000000*(1+Inputs!$B$28) -> 0.355536 | J30: =Inputs!$B$9*((Inputs!$B$14+Inputs!$B$24)*Inputs!$B$65+Inputs!$B$25*Inputs!$C$65)/1000000*(1+Inputs!$B$28) -> 1.4688 | K30: =Inputs!$B$9*((Inputs!$B$14+Inputs!$B$24)*Inputs!$B$66+Inputs!$B$25*Inputs!$C$66)/1000000*(1+Inputs!$B$28) -> 2.9376
A31: Cost per contract (model + hosting, today's volume) | I31: =I27/Inputs!$B$5 -> 0.07577178 | J31: =J27/Inputs!$B$5 -> 3.6700923 | K31: =K27/Inputs!$B$5 -> 4.0448133

Sheet Way2_Tokens_By_Document
A1: Way 2: cost by document type (input tokens, output tokens, volumes)
A2: Top-down check on Way 1: how many documents of each kind reach the model each month, how many tokens go in and come out. Priced at the main model (conservative).
A4: Document / interaction | B4: Volume per month | C4: Tokens in the document | D4: Times the text is sent to the model | E4: Instructions + context per document | F4: Input tokens per document | G4: Output tokens per document | H4: Input tokens per month | I4: Output tokens per month | J4: A Prototype $/month | K4: B Recommended $/month | L4: C Premium $/month
A5: Incoming drafts: first review (MSA, SOW, NDA, BAA, partner) | B5: =Inputs!$B$5 -> 9 | C5: =Inputs!$B$13 -> 15000 | D5: 1.19 | E5: =ROUNDUP(Inputs!$B$13/Inputs!$B$16,0)*Inputs!$B$17+300+Inputs!$B$21*Inputs!$B$22 -> 9000 | F5: =C5*D5+E5 -> 26850 | G5: =ROUNDUP(Inputs!$B$13/Inputs!$B$16,0)*Inputs!$B$18+Inputs!$B$20+Inputs!$B$21*Inputs!$B$23 -> 4540 | H5: =B5*F5*(1+Inputs!$B$28) -> 289980 | I5: =B5*G5*(1+Inputs!$B$28) -> 49032 | J5: =(H5*Inputs!$B$64+I5*Inputs!$C$64)/1000000 -> 0.20982348 | K5: =(H5*Inputs!$B$65+I5*Inputs!$C$65)/1000000 -> 1.07028 | L5: =(H5*Inputs!$B$66+I5*Inputs!$C$66)/1000000 -> 2.14056
A6: Incoming drafts: revised versions re-reviewed | B6: =Inputs!$B$5*(Inputs!$B$7-1) -> 4.5 | C6: =Inputs!$B$13 -> 15000 | D6: 1.19 | E6: =E5 -> 9000 | F6: =C6*D6+E6 -> 26850 | G6: =G5 -> 4540 | H6: =B6*F6*(1+Inputs!$B$28) -> 144990 | I6: =B6*G6*(1+Inputs!$B$28) -> 24516 | J6: =(H6*Inputs!$B$64+I6*Inputs!$C$64)/1000000 -> 0.10491174 | K6: =(H6*Inputs!$B$65+I6*Inputs!$C$65)/1000000 -> 0.53514 | L6: =(H6*Inputs!$B$66+I6*Inputs!$C$66)/1000000 -> 1.07028
A7: Signed contracts: new, read once for the register | B7: =Inputs!$B$8 -> 6 | C7: =Inputs!$B$14 -> 15000 | D7: 1 | E7: =Inputs!$B$24 -> 400 | F7: =C7*D7+E7 -> 15400 | G7: =Inputs!$B$25 -> 1000 | H7: =B7*F7*(1+Inputs!$B$28) -> 110880 | I7: =B7*G7*(1+Inputs!$B$28) -> 7200 | J7: =(H7*Inputs!$B$64+I7*Inputs!$C$64)/1000000 -> 0.0711072 | K7: =(H7*Inputs!$B$65+I7*Inputs!$C$65)/1000000 -> 0.29376 | L7: =(H7*Inputs!$B$66+I7*Inputs!$C$66)/1000000 -> 0.58752
A8: Waivers, letters, amendments | B8: =Inputs!$B$10 -> 2 | C8: =Inputs!$B$15 -> 3000 | D8: 1 | E8: =Inputs!$B$24 -> 400 | F8: =C8*D8+E8 -> 3400 | G8: =Inputs!$B$25 -> 1000 | H8: =B8*F8*(1+Inputs!$B$28) -> 8160 | I8: =B8*G8*(1+Inputs!$B$28) -> 2400 | J8: =(H8*Inputs!$B$64+I8*Inputs!$C$64)/1000000 -> 0.0067104 | K8: =(H8*Inputs!$B$65+I8*Inputs!$C$65)/1000000 -> 0.04032 | L8: =(H8*Inputs!$B$66+I8*Inputs!$C$66)/1000000 -> 0.08064
A9: Negotiation + meeting notes (search index only) | B9: 4 | C9: 2000 | D9: 0 | E9: 0 | F9: =C9*D9+E9 -> 0 | G9: 0 | H9: =B9*F9*(1+Inputs!$B$28) -> 0 | I9: =B9*G9*(1+Inputs!$B$28) -> 0 | J9: =(H9*Inputs!$B$64+I9*Inputs!$C$64)/1000000 -> 0 | K9: =(H9*Inputs!$B$65+I9*Inputs!$C$65)/1000000 -> 0 | L9: =(H9*Inputs!$B$66+I9*Inputs!$C$66)/1000000 -> 0
A10: Tracker rows, playbook, entity rules (code only) | B10: 48 | C10: 0 | D10: 0 | E10: 0 | F10: =C10*D10+E10 -> 0 | G10: 0 | H10: =B10*F10*(1+Inputs!$B$28) -> 0 | I10: =B10*G10*(1+Inputs!$B$28) -> 0 | J10: =(H10*Inputs!$B$64+I10*Inputs!$C$64)/1000000 -> 0 | K10: =(H10*Inputs!$B$65+I10*Inputs!$C$65)/1000000 -> 0 | L10: =(H10*Inputs!$B$66+I10*Inputs!$C$66)/1000000 -> 0
A11: 'Ask the contracts' questions | B11: =Inputs!$B$11 -> 80 | C11: 0 | D11: 0 | E11: =Inputs!$B$26 -> 4000 | F11: =C11*D11+E11 -> 4000 | G11: =Inputs!$B$27 -> 400 | H11: =B11*F11*(1+Inputs!$B$28) -> 384000 | I11: =B11*G11*(1+Inputs!$B$28) -> 38400 | J11: =(H11*Inputs!$B$64+I11*Inputs!$C$64)/1000000 -> 0.256896 | K11: =(H11*Inputs!$B$65+I11*Inputs!$C$65)/1000000 -> 1.152 | L11: =(H11*Inputs!$B$66+I11*Inputs!$C$66)/1000000 -> 2.304
A12: Outcome emails (built from the playbook) | B12: =Inputs!$B$5 -> 9 | C12: 0 | D12: 0 | E12: 0 | F12: =C12*D12+E12 -> 0 | G12: 0 | H12: =B12*F12*(1+Inputs!$B$28) -> 0 | I12: =B12*G12*(1+Inputs!$B$28) -> 0 | J12: =(H12*Inputs!$B$64+I12*Inputs!$C$64)/1000000 -> 0 | K12: =(H12*Inputs!$B$65+I12*Inputs!$C$65)/1000000 -> 0 | L12: =(H12*Inputs!$B$66+I12*Inputs!$C$66)/1000000 -> 0
A13: Model cost per month | H13: =SUM(H5:H12) -> 938010 | I13: =SUM(I5:I12) -> 121548 | J13: =SUM(J5:J12) -> 0.64944882 | K13: =SUM(K5:K12) -> 3.0915 | L13: =SUM(L5:L12) -> 6.183
A14: Hosting + storage per month | J14: =Inputs!$B$30 -> 0 | K14: =Inputs!$B$31+Inputs!$B$32 -> 30 | L14: =Inputs!$B$31+Inputs!$B$32 -> 30
A15: Total per year | J15: =(J13+J14)*12 -> 7.7933858 | K15: =(K13+K14)*12 -> 397.098 | L15: =(L13+L14)*12 -> 434.196
A16: One-time: signed archive into the register | B16: =Inputs!$B$9 -> 30 | H16: =B16*(Inputs!$B$14+Inputs!$B$24) -> 462000 | I16: =B16*Inputs!$B$25 -> 30000 | J16: =(H16*Inputs!$B$64+I16*Inputs!$C$64)/1000000 -> 0.29628 | K16: =(H16*Inputs!$B$65+I16*Inputs!$C$65)/1000000 -> 1.224 | L16: =(H16*Inputs!$B$66+I16*Inputs!$C$66)/1000000 -> 2.448
A17: Check: Way 2 vs Way 1 yearly total (B Recommended) | K17: =K15/Way1_Per_Review!J28 -> 1.0018367 | L17: Way 2 prices everything at the main model, so it should be a bit higher.

Sheet Cost_of_Status_Quo
A1: What the current way of working costs: past losses and deals in hand
A3: A. Past losses on record
A4: What happened | B4: Cost ($) | C4: Counted in yearly cost? | D4: Source | E4: What ContractLens does about it
A5: Brightwater: settlement credit (uncapped LD, English law, signed at an airport) | B5: 9000 | C5: Yes | D5: Tracker C-018 credit note; PRD 2.3 | E5: LD and entity/law rules flag it before signing
A6: Brightwater: legal fees | B6: 14200 | C6: Yes | D6: PRD 2.3; April 2026 post-mortem | E6: Same
A7: Brightwater: about two weeks of senior time | B7: =Inputs!$B$43*Inputs!$B$35 -> 12000 | C7: Yes | D7: Post-mortem; hours x hourly value | E7: Same
A8: ShopSwift: SOW sat 9 days in the queue, $55,000 budget moved a quarter | B8: 55000 | C8: No (revenue delayed, not lost) | D8: Tracker C-019 | E8: Queue sorted by deadline; brief in minutes
A9: Kessler Mobility: EUR 120k MSA walked away over unlimited liability | B9: 130000 | C9: No (right call) | D9: Tracker C-015; negotiation notes | E9: Flags it on day one so the counter-offer goes out early
A10: One Brightwater-type incident costs | B10: =SUM(B5:B7) -> 35200
A12: B. Deals in hand (tracker, 28 Sep 2026) and the risk ContractLens found
A13: Deal | B13: Value ($) | C13: Deadline | D13: Risk found in review | E13: If missed
A14: Harrington Health MSA + BAA (C-023, C-046) | B14: 210000 | C14: 1 Oct | D14: Patient data sent before a BAA; two subcontractor BAAs missing; LD 2% a day, uncapped | E14: HIPAA breach exposure on a $210k deal
A15: Gulf Crown Hotels MSA (C-025) | B15: 140000 | C15: 10 Oct | D15: Collides with the Al Noor GCC non-compete (signed Mar 2025, active to Sep 2029) | E15: Breach of a $185k Al Noor contract
A16: Rheinwerk Analytics MSA + SOW (C-028) | B16: 96000 | C16: 15 Oct | D16: PipeKit IP was assigned to Northwind; GDPR DPA needed | E16: IP warranty breach; GDPR exposure
A17: FinEdge Bank MSA (C-022) | B17: 95000 | C17: awaiting client | D17: Markup with the client since 18 Aug | E17: Deal stalls
A18: Lakeshore Grocers SOW + rate card (C-026) | B18: 64000 | C18: 3 Oct | D18: $72/hr senior DE vs Crestline's most-favoured $85/hr | E18: Retroactive price cut owed to Crestline
A19: TravelHub MSA (C-024) | B19: 52000 | C19: - | D19: Wrong AtliQ entity; Al Noor hotel conflict | E19: Tax/invoicing mess; Al Noor breach
A20: Sunrise Foods SOW-2 (C-029) | B20: 45000 | C20: 8 Oct | D20: Only looks risky: within standard | E20: Delay for nothing (fast-tracked)
A21: BlueOrchid Hotels pilot (C-027) | B21: 38000 | C21: 5 Oct | D21: Al Noor conflict if Dubai/Muscat hotels are in scope | E21: Breach of Al Noor contract
A22: Deal value waiting on review | B22: =SUM(B14:B21) -> 740000
A23: Of which carry a blocker-level risk (Harrington, Gulf Crown, Rheinwerk, Lakeshore, TravelHub, BlueOrchid) | B23: =B14+B15+B16+B18+B19+B21 -> 600000
A24: Al Noor contract that a missed conflict would breach | B24: 185000 | D24: Negotiation notes: '$185k, 14 properties, first Gulf logo'
A26: C. Yearly cost: without AI vs with ContractLens (today's 9 contracts a month)
A27: Cost line | B27: Without AI ($/yr) | C27: With ContractLens ($/yr) | D27: How it is calculated | E27: Saving ($/yr)
A28: Karandeep's review time | B28: =Inputs!$B$5*12*Inputs!$B$36*Inputs!$B$35 -> 56700 | C28: =Inputs!$B$5*12*Inputs!$B$37*Inputs!$B$35 -> 8100 | D28: contracts x 12 x hours x hourly value | E28: =B28-C28 -> 48600
A29: Outside counsel | B29: =Inputs!$B$39*12*Inputs!$B$38/Inputs!$B$34 -> 34285.714 | C29: =Inputs!$B$40*12*Inputs!$B$38/Inputs!$B$34 -> 17142.857 | D29: reviews a month x 12 x ₹1,20,000 / rate | E29: =B29-C29 -> 17142.857
A30: Expected cost of a Brightwater-type incident | B30: =Inputs!$B$41*B10 -> 35200 | C30: =Inputs!$B$41*(1-Inputs!$B$42)*B10 -> 7040 | D30: incidents a year x cost of one (risk-weighted) | E30: =B30-C30 -> 28160
A31: ContractLens model + hosting (scenario B) | B31: 0 | C31: =Way1_Per_Review!J28 -> 396.36997 | D31: Way 1 yearly total, recommended models | E31: =B31-C31 -> -396.36997
A32: Total per year | B32: =SUM(B28:B31) -> 126185.71 | C32: =SUM(C28:C31) -> 32679.227 | E32: =SUM(E28:E31) -> 93506.487
A33: Karandeep's hours on contracts per month | B33: =Inputs!$B$5*Inputs!$B$36 -> 31.5 | C33: =Inputs!$B$5*Inputs!$B$37 -> 4.5
A34: One-time cost to go live (engineering + playbook + archive load) | C34: =Inputs!$B$44*Inputs!$B$45+Inputs!$B$46*Inputs!$B$35+Way1_Per_Review!J30 -> 5701.4688
A35: Payback (months) | C35: =C34/(E32/12) -> 0.73168855
A36: Return on yearly running cost (saving / model + hosting) | C36: =E32/C31 -> 235.90709
